File: kobaken_MCE/sample_squid.dat
[Header]
TITLE
BYAPP
FILEOPENTIME

INFO

INFO
INFO
INFO
INFO
INFO
INFO
INFO


INFO


STARTUPAXIS
STARTUPAXIS


STARTUPGROUP
FIELDGROUP
FIELDGROUP

PLOT_APPEARANCE

[Data]
Time,Comment,Field (Oe),Temperature (K),Long Moment (emu),Long Scan Std Dev,Long Algorithm,Long Reg Fit,Long Percent Error (%),Trans Moment (emu),Trans Scan Std Dev,Trans Algorithm,Trans Reg Fit,Trans Percent Error (%),Long Moment [w/o ABS] (emu),Long Scan Std Dev [w/o ABS],Long Reg Fit [w/o ABS],Long Percent Error [w/o ABS] (%),Trans Moment [w/o ABS] (emu),Trans Scan Std Dev [w/o ABS],Trans Reg Fit [w/o ABS],Trans Percent Error [w/o ABS] (%),Points per Scan,Scans per Measurement,Scan Length (cm),Delta Temp (K),Rot Position (deg),Error,EC Comp. Running,Using ABS,
1652350721.937,,0.000000e+000,9.997683e+000,-3.009089e-004,2.792641e-008,3,9.935415e-001,9.280687e-003,,,,,,,,,,,,,,32,2,4.000000e+000,1.024246e-003,0.000000e+000,0,1,0,
1652350855.906,,2.000000e+002,9.992390e+000,1.986513e-003,4.463286e-007,3,9.933500e-001,2.246794e-002,,,,,,,,,,,,,,32,2,4.000000e+000,3.072739e-003,0.000000e+000,0,0,0,
1652350973.343,,4.000000e+002,9.995975e+000,4.342944e-003,1.458680e-007,3,9.930679e-001,3.358735e-003,,,,,,,,,,,,,,32,2,4.000000e+000,3.755569e-003,0.000000e+000,0,0,0,
1652351127.187,,6.000000e+002,9.995974e+000,6.769283e-003,8.324002e-007,3,9.932638e-001,1.229673e-002,,,,,,,,,,,,,,32,2,4.000000e+000,5.807877e-003,0.000000e+000,0,0,0,
1652351243.937,,8.000000e+002,9.996658e+000,9.375893e-003,3.080013e-006,3,9.929210e-001,3.285034e-002,,,,,,,,,,,,,,32,2,4.000000e+000,4.440308e-003,0.000000e+000,0,0,0,
1652351362.500,,1.000000e+003,9.996828e+000,1.208956e-002,7.672043e-006,3,9.930665e-001,6.346006e-002,,,,,,,,,,,,,,32,2,4.000000e+000,5.123138e-003,0.000000e+000,0,0,0,
1652351479.546,,1.200000e+003,1.000025e+001,1.449831e-002,1.916376e-007,3,9.936116e-001,1.321793e-003,,,,,,,,,,,,,,32,2,4.000000e+000,4.818916e-003,0.000000e+000,0,1,0,
1652351601.468,,1.400000e+003,9.998026e+000,1.689482e-002,3.132038e-006,3,9.927593e-001,1.853844e-002,,,,,,,,,,,,,,32,2,4.000000e+000,4.109383e-003,0.000000e+000,0,1,0,
1652351752.640,,1.600000e+003,9.993244e+000,1.923933e-002,1.641093e-006,3,9.933556e-001,8.529885e-003,,,,,,,,,,,,,,32,2,4.000000e+000,2.388954e-003,0.000000e+000,0,1,0,
1652351872.250,,1.800000e+003,9.996914e+000,2.157746e-002,1.715377e-005,3,9.928421e-001,7.949855e-002,,,,,,,,,,,,,,32,2,4.000000e+000,5.466461e-003,0.000000e+000,0,0,0,
1652351995.734,,2.000000e+003,9.997860e+000,2.394782e-002,1.190649e-006,3,9.929304e-001,4.971844e-003,,,,,,,,,,,,,,32,2,4.000000e+000,8.909225e-003,0.000000e+000,0,0,0,
1652352117.671,,2.200000e+003,9.998978e+000,2.630127e-002,9.720117e-006,3,9.927976e-001,3.695684e-002,,,,,,,,,,,,,,32,2,4.000000e+000,1.235008e-002,0.000000e+000,0,0,0,
1652352236.156,,2.400000e+003,9.998726e+000,2.862336e-002,1.797827e-006,3,9.929289e-001,6.280979e-003,,,,,,,,,,,,,,32,2,4.000000e+000,1.510143e-002,0.000000e+000,0,1,0,
1652352358.593,,2.600000e+003,1.000010e+001,3.098527e-002,6.131049e-006,3,9.929044e-001,1.978698e-002,,,,,,,,,,,,,,32,2,4.000000e+000,1.407051e-002,0.000000e+000,0,1,0,
1652352483.453,,2.800000e+003,1.000234e+001,3.332819e-002,1.406651e-006,3,9.928904e-001,4.220604e-003,,,,,,,,,,,,,,32,2,4.000000e+000,2.648926e-002,0.000000e+000,0,1,0,
1652352600.828,,3.000000e+003,1.001775e+001,3.567244e-002,9.293380e-006,3,9.928767e-001,2.605198e-002,,,,,,,,,,,,,,32,2,4.000000e+000,1.086740e-001,0.000000e+000,0,0,0,
1652352721.062,,3.200000e+003,1.000167e+001,3.803474e-002,7.697068e-006,3,9.928931e-001,2.023694e-002,,,,,,,,,,,,,,32,2,4.000000e+000,1.092310e-001,0.000000e+000,0,0,0,
1652352839.015,,3.400000e+003,9.998730e+000,4.038223e-002,5.426407e-006,3,9.929188e-001,1.343761e-002,,,,,,,,,,,,,,32,2,4.000000e+000,1.407146e-002,0.000000e+000,0,0,0,
1652352958.109,,3.600000e+003,9.996060e+000,4.273604e-002,9.693775e-007,3,9.928492e-001,2.268290e-003,,,,,,,,,,,,,,32,2,4.000000e+000,8.195877e-003,0.000000e+000,0,0,0,
1652353091.546,,3.800000e+003,9.996151e+000,4.508451e-002,1.211722e-006,3,9.930608e-001,2.687668e-003,,,,,,,,,,,,,,32,2,4.000000e+000,9.243011e-003,0.000000e+000,0,0,0,
1652353215.531,,4.000000e+003,1.000044e+001,4.745660e-002,3.116234e-006,3,9.928594e-001,6.566492e-003,,,,,,,,,,,,,,32,2,4.000000e+000,1.031017e-002,0.000000e+000,0,1,0,
1652353332.859,,4.200000e+003,9.998807e+000,4.980910e-002,6.919986e-006,3,9.928545e-001,1.389302e-002,,,,,,,,,,,,,,32,2,4.000000e+000,1.166630e-002,0.000000e+000,0,1,0,
1652353454.171,,4.400000e+003,9.995720e+000,5.217768e-002,5.526505e-006,3,9.927965e-001,1.059171e-002,,,,,,,,,,,,,,32,2,4.000000e+000,8.195877e-003,0.000000e+000,0,1,0,
1652353576.343,,4.600000e+003,9.997341e+000,5.453640e-002,2.676325e-006,3,9.928137e-001,4.907410e-003,,,,,,,,,,,,,,32,2,4.000000e+000,7.169724e-003,0.000000e+000,0,0,0,
1652353696.218,,4.800000e+003,9.995548e+000,5.688317e-002,5.083964e-006,3,9.927616e-001,8.937553e-003,,,,,,,,,,,,,,32,2,4.000000e+000,6.145477e-003,0.000000e+000,0,0,0,
1652353814.515,,5.000000e+003,9.996145e+000,5.923454e-002,3.271649e-006,3,9.927633e-001,5.523212e-003,,,,,,,,,,,,,,32,2,4.000000e+000,7.169724e-003,0.000000e+000,0,0,0,
1652353940.859,,6.000000e+003,9.996402e+000,7.097196e-002,6.848863e-007,3,9.927307e-001,9.650097e-004,,,,,,,,,,,,,,32,2,4.000000e+000,5.466461e-003,0.000000e+000,0,0,0,
1652354066.937,,6.500000e+003,9.997858e+000,7.678814e-002,6.037536e-006,3,9.926926e-001,7.862589e-003,,,,,,,,,,,,,,32,2,4.000000e+000,8.561134e-003,0.000000e+000,0,1,0,
1652354191.781,,7.000000e+003,9.997343e+000,8.259352e-002,8.924595e-006,3,9.926758e-001,1.080544e-002,,,,,,,,,,,,,,32,2,4.000000e+000,8.543968e-003,0.000000e+000,0,1,0,
1652354317.937,,7.500000e+003,9.996316e+000,8.834768e-002,8.555810e-006,3,9.926594e-001,9.684250e-003,,,,,,,,,,,,,,32,2,4.000000e+000,8.537292e-003,0.000000e+000,0,1,0,
1652354500.968,,8.000000e+003,9.992306e+000,9.406196e-002,9.799143e-007,3,9.933473e-001,1.041775e-003,,,,,,,,,,,,,,32,2,4.000000e+000,8.874893e-003,0.000000e+000,0,0,0,
1652354627.703,,8.500000e+003,9.996747e+000,9.978769e-002,2.191636e-006,3,9.926976e-001,2.196299e-003,,,,,,,,,,,,,,32,2,4.000000e+000,9.919167e-003,0.000000e+000,0,0,0,
1652354753.531,,9.000000e+003,9.995975e+000,1.054915e-001,1.895028e-005,3,9.926121e-001,1.796379e-002,,,,,,,,,,,,,,32,2,4.000000e+000,6.827354e-003,0.000000e+000,0,0,0,
1652354880.828,,9.500000e+003,1.000034e+001,1.111367e-001,1.512545e-005,3,9.926455e-001,1.360977e-002,,,,,,,,,,,,,,32,2,4.000000e+000,4.812241e-003,0.000000e+000,0,1,0,
1652355003.031,,1.000000e+004,9.998024e+000,1.167321e-001,7.265065e-006,3,9.927350e-001,6.223706e-003,,,,,,,,,,,,,,32,2,4.000000e+000,3.416061e-003,0.000000e+000,0,1,0,
1652355128.781,,1.200000e+004,9.997255e+000,1.389147e-001,3.053539e-005,3,9.925942e-001,2.198139e-002,,,,,,,,,,,,,,32,2,4.000000e+000,5.464554e-003,0.000000e+000,0,1,0,
1652355258.078,,1.400000e+004,9.997085e+000,1.605938e-001,4.102996e-005,3,9.924997e-001,2.554891e-002,,,,,,,,,,,,,,32,2,4.000000e+000,6.827354e-003,0.000000e+000,0,0,0,
1652355393.406,,1.600000e+004,9.996231e+000,1.818438e-001,2.324399e-005,3,9.925581e-001,1.278239e-002,,,,,,,,,,,,,,32,2,4.000000e+000,7.513046e-003,0.000000e+000,0,0,0,
1652355528.484,,1.800000e+004,9.994864e+000,2.027501e-001,2.111557e-005,3,9.925530e-001,1.041458e-002,,,,,,,,,,,,,,32,2,4.000000e+000,6.828308e-003,0.000000e+000,0,0,0,
1652355664.500,,2.000000e+004,9.998373e+000,2.233237e-001,3.445505e-005,3,9.925488e-001,1.542830e-002,,,,,,,,,,,,,,32,2,4.000000e+000,8.569717e-003,0.000000e+000,0,1,0,
1652355794.609,,2.200000e+004,9.996914e+000,2.436430e-001,5.109252e-005,3,9.925092e-001,2.097023e-002,,,,,,,,,,,,,,32,2,4.000000e+000,6.147385e-003,0.000000e+000,0,1,0,
1652355932.265,,2.400000e+004,9.997426e+000,2.636778e-001,5.759367e-005,3,9.925005e-001,2.184244e-002,,,,,,,,,,,,,,32,2,4.000000e+000,6.149292e-003,0.000000e+000,0,1,0,
1652356070.578,,2.600000e+004,9.995892e+000,2.834326e-001,4.452815e-005,3,9.924966e-001,1.571031e-002,,,,,,,,,,,,,,32,2,4.000000e+000,1.025105e-002,0.000000e+000,0,0,0,
1652356203.390,,2.800000e+004,9.996317e+000,3.029616e-001,6.545406e-005,3,9.924643e-001,2.160473e-002,,,,,,,,,,,,,,32,2,4.000000e+000,5.804062e-003,0.000000e+000,0,0,0,
1652356338.906,,3.000000e+004,9.996229e+000,3.222132e-001,6.459005e-005,3,9.924601e-001,2.004575e-002,,,,,,,,,,,,,,32,2,4.000000e+000,2.733231e-003,0.000000e+000,0,0,0,
1652356478.328,,3.200000e+004,9.998285e+000,3.411909e-001,6.918405e-005,3,9.925258e-001,2.027722e-002,,,,,,,,,,,,,,32,2,4.000000e+000,8.900642e-003,0.000000e+000,0,1,0,
1652356613.718,,3.400000e+004,9.996405e+000,3.599488e-001,5.481198e-005,3,9.924309e-001,1.522772e-002,,,,,,,,,,,,,,32,2,4.000000e+000,8.203506e-003,0.000000e+000,0,1,0,
1652356748.718,,3.600000e+004,9.995719e+000,3.784627e-001,6.395784e-005,3,9.925003e-001,1.689938e-002,,,,,,,,,,,,,,32,2,4.000000e+000,6.828308e-003,0.000000e+000,0,1,0,
1652356881.265,,3.800000e+004,9.997343e+000,3.967823e-001,6.846756e-005,3,9.924959e-001,1.725570e-002,,,,,,,,,,,,,,32,2,4.000000e+000,7.180214e-003,0.000000e+000,0,1,0,
1652357016.921,,4.000000e+004,9.997172e+000,4.148883e-001,6.511688e-005,3,9.924843e-001,1.569504e-002,,,,,,,,,,,,,,32,2,4.000000e+000,8.886337e-003,0.000000e+000,0,1,0,
1652357155.781,,4.200000e+004,9.997175e+000,4.328519e-001,7.009021e-005,3,9.924245e-001,1.619265e-002,,,,,,,,,,,,,,32,2,4.000000e+000,1.094723e-002,0.000000e+000,0,0,0,
1652357371.703,,4.400000e+004,1.000145e+001,4.508758e-001,1.960039e-004,3,9.919121e-001,4.347182e-002,,,,,,,,,,,,,,32,2,4.000000e+000,2.070427e-003,0.000000e+000,0,1,0,
1652357568.234,,4.600000e+004,9.999906e+000,4.684947e-001,1.545736e-004,3,9.920266e-001,3.299367e-002,,,,,,,,,,,,,,32,2,4.000000e+000,1.032829e-003,0.000000e+000,0,1,0,
1652357767.796,,4.800000e+004,1.000068e+001,4.859675e-001,2.791386e-004,3,9.919394e-001,5.743976e-002,,,,,,,,,,,,,,32,2,4.000000e+000,3.087997e-003,0.000000e+000,0,1,0,
1652357974.484,,5.000000e+004,1.000093e+001,5.032881e-001,1.748251e-004,3,9.920014e-001,3.473658e-002,,,,,,,,,,,,,,32,2,4.000000e+000,1.029968e-003,0.000000e+000,0,1,0,
1652368242.218,,0.000000e+000,1.999846e+001,-3.164643e-004,4.383485e-009,3,9.912454e-001,1.385144e-003,,,,,,,,,,,,,,32,2,4.000000e+000,7.360458e-003,0.000000e+000,0,0,0,
1652368377.046,,2.000000e+002,1.999876e+001,1.870558e-003,6.953407e-007,3,9.937475e-001,3.717289e-002,,,,,,,,,,,,,,32,2,4.000000e+000,3.688812e-003,0.000000e+000,0,0,0,
1652368492.578,,4.000000e+002,1.999800e+001,4.131207e-003,1.493250e-006,3,9.932294e-001,3.614560e-002,,,,,,,,,,,,,,32,2,4.000000e+000,3.068924e-003,0.000000e+000,0,1,0,
1652368643.062,,6.000000e+002,2.000199e+001,6.466588e-003,6.414223e-007,3,9.932773e-001,9.919023e-003,,,,,,,,,,,,,,32,2,4.000000e+000,5.531311e-003,0.000000e+000,0,1,0,
1652368760.593,,8.000000e+002,1.999953e+001,9.062626e-003,9.483041e-008,3,9.929409e-001,1.046390e-003,,,,,,,,,,,,,,32,2,4.000000e+000,3.068924e-003,0.000000e+000,0,1,0,
1652368881.578,,1.000000e+003,1.999876e+001,1.163660e-002,1.414554e-006,3,9.929835e-001,1.215608e-002,,,,,,,,,,,,,,32,2,4.000000e+000,3.068924e-003,0.000000e+000,0,1,0,
1652368998.140,,1.200000e+003,1.999861e+001,1.394535e-002,1.814290e-006,3,9.930246e-001,1.301000e-002,,,,,,,,,,,,,,32,2,4.000000e+000,7.369995e-003,0.000000e+000,0,0,0,
1652369120.593,,1.400000e+003,1.999846e+001,1.622906e-002,4.150148e-006,3,9.929999e-001,2.557232e-002,,,,,,,,,,,,,,32,2,4.000000e+000,2.449036e-003,0.000000e+000,0,0,0,
1652369257.109,,1.600000e+003,1.999953e+001,1.850095e-002,1.605532e-006,3,9.932287e-001,8.678108e-003,,,,,,,,,,,,,,32,2,4.000000e+000,3.068924e-003,0.000000e+000,0,0,0,
1652369381.265,,1.800000e+003,1.999784e+001,2.078622e-002,1.567863e-005,3,9.927515e-001,7.542799e-002,,,,,,,,,,,,,,32,2,4.000000e+000,3.068924e-003,0.000000e+000,0,0,0,
1652369501.921,,2.000000e+003,1.999723e+001,2.303630e-002,2.145406e-005,3,9.925724e-001,9.313154e-002,,,,,,,,,,,,,,32,2,4.000000e+000,3.679276e-003,0.000000e+000,0,0,0,
1652369622.406,,2.200000e+003,1.999784e+001,2.531878e-002,1.868950e-006,3,9.926703e-001,7.381674e-003,,,,,,,,,,,,,,32,2,4.000000e+000,4.909515e-003,0.000000e+000,0,0,0,
1652369738.750,,2.400000e+003,1.999999e+001,2.757430e-002,4.586104e-006,3,9.926718e-001,1.663181e-002,,,,,,,,,,,,,,32,2,4.000000e+000,9.208679e-003,0.000000e+000,0,1,0,
1652369860.781,,2.600000e+003,2.000137e+001,2.985483e-002,1.780704e-006,3,9.927784e-001,5.964543e-003,,,,,,,,,,,,,,32,2,4.000000e+000,3.070831e-003,0.000000e+000,0,1,0,
1652369977.281,,2.800000e+003,2.000045e+001,3.210926e-002,6.116562e-006,3,9.927983e-001,1.904921e-002,,,,,,,,,,,,,,32,2,4.000000e+000,2.460480e-003,0.000000e+000,0,1,0,
1652370095.984,,3.000000e+003,2.000199e+001,3.440208e-002,4.601910e-006,3,9.927665e-001,1.337684e-002,,,,,,,,,,,,,,32,2,4.000000e+000,1.840591e-003,0.000000e+000,0,1,0,
1652370219.859,,3.200000e+003,1.999969e+001,3.669380e-002,3.311163e-006,3,9.927633e-001,9.023767e-003,,,,,,,,,,,,,,32,2,4.000000e+000,9.820938e-003,0.000000e+000,0,1,0,
1652370341.250,,3.400000e+003,1.999938e+001,3.897924e-002,4.485844e-008,3,9.927069e-001,1.150829e-004,,,,,,,,,,,,,,32,2,4.000000e+000,7.369995e-003,0.000000e+000,0,0,0,
1652370463.500,,3.600000e+003,1.999892e+001,4.126804e-002,2.531446e-006,3,9.927144e-001,6.134158e-003,,,,,,,,,,,,,,32,2,4.000000e+000,1.412010e-002,0.000000e+000,0,0,0,
1652370587.000,,3.800000e+003,1.999830e+001,4.356489e-002,1.087919e-006,3,9.927033e-001,2.497237e-003,,,,,,,,,,,,,,32,2,4.000000e+000,3.688812e-003,0.000000e+000,0,0,0,
1652370723.859,,4.000000e+003,1.999800e+001,4.584641e-002,1.037866e-006,3,9.929880e-001,2.263789e-003,,,,,,,,,,,,,,32,2,4.000000e+000,2.458572e-003,0.000000e+000,0,0,0,
1652370843.890,,4.200000e+003,1.999738e+001,4.812802e-002,1.588412e-006,3,9.927277e-001,3.300389e-003,,,,,,,,,,,,,,32,2,4.000000e+000,4.909515e-003,0.000000e+000,0,0,0,
1652370967.812,,4.400000e+003,1.999631e+001,5.042175e-002,2.167930e-006,3,9.926670e-001,4.299593e-003,,,,,,,,,,,,,,32,2,4.000000e+000,3.070831e-003,0.000000e+000,0,0,0,
1652371089.046,,4.600000e+003,1.999907e+001,5.270542e-002,4.770497e-006,3,9.925900e-001,9.051246e-003,,,,,,,,,,,,,,32,2,4.000000e+000,4.909515e-003,0.000000e+000,0,0,0,
1652371206.984,,4.800000e+003,2.000014e+001,5.496113e-002,2.810669e-006,3,9.926150e-001,5.113922e-003,,,,,,,,,,,,,,32,2,4.000000e+000,7.369995e-003,0.000000e+000,0,1,0,
1652371329.968,,5.000000e+003,2.000168e+001,5.722638e-002,1.780704e-006,3,9.926903e-001,3.111684e-003,,,,,,,,,,,,,,32,2,4.000000e+000,1.230240e-003,0.000000e+000,0,1,0,
1652371456.515,,6.000000e+003,2.000782e+001,6.842186e-002,6.780376e-006,3,9.926054e-001,9.909664e-003,,,,,,,,,,,,,,32,2,4.000000e+000,7.989883e-003,0.000000e+000,0,1,0,
1652371583.812,,6.500000e+003,1.999968e+001,7.395914e-002,4.040833e-006,3,9.926258e-001,5.463602e-003,,,,,,,,,,,,,,32,2,4.000000e+000,2.449036e-003,0.000000e+000,0,1,0,
1652371711.156,,7.000000e+003,2.000229e+001,7.947108e-002,5.663485e-006,3,9.926156e-001,7.126473e-003,,,,,,,,,,,,,,32,2,4.000000e+000,5.519867e-003,0.000000e+000,0,1,0,
1652371837.468,,7.500000e+003,1.999769e+001,8.494243e-002,9.245967e-006,3,9.926181e-001,1.088498e-002,,,,,,,,,,,,,,32,2,4.000000e+000,6.139755e-003,0.000000e+000,0,0,0,
1652371978.250,,8.000000e+003,1.999692e+001,9.035668e-002,1.053671e-008,3,9.928941e-001,1.166124e-005,,,,,,,,,,,,,,32,2,4.000000e+000,5.531311e-003,0.000000e+000,0,0,0,
1652372105.421,,8.500000e+003,1.999738e+001,9.578051e-002,1.398222e-005,3,9.925997e-001,1.459819e-002,,,,,,,,,,,,,,32,2,4.000000e+000,5.529404e-003,0.000000e+000,0,0,0,
1652372232.890,,9.000000e+003,1.999784e+001,1.011423e-001,1.349753e-005,3,9.925611e-001,1.334509e-002,,,,,,,,,,,,,,32,2,4.000000e+000,5.519867e-003,0.000000e+000,0,0,0,
1652372360.343,,9.500000e+003,1.999738e+001,1.064469e-001,2.739545e-006,3,9.926533e-001,2.573625e-003,,,,,,,,,,,,,,32,2,4.000000e+000,3.679276e-003,0.000000e+000,0,0,0,
1652372489.937,,1.000000e+004,1.999738e+001,1.117832e-001,5.461178e-005,3,9.926443e-001,4.885507e-002,,,,,,,,,,,,,,32,2,4.000000e+000,3.679276e-003,0.000000e+000,0,1,0,
1652372622.578,,1.200000e+004,2.000137e+001,1.325583e-001,9.988803e-006,3,9.926243e-001,7.535401e-003,,,,,,,,,,,,,,32,2,4.000000e+000,4.301071e-003,0.000000e+000,0,1,0,
1652372756.375,,1.400000e+004,2.000092e+001,1.530268e-001,3.309581e-005,3,9.925424e-001,2.162747e-002,,,,,,,,,,,,,,32,2,4.000000e+000,6.750107e-003,0.000000e+000,0,1,0,
1652372889.218,,1.600000e+004,1.999891e+001,1.731854e-001,2.914454e-005,3,9.925697e-001,1.682852e-002,,,,,,,,,,,,,,32,2,4.000000e+000,3.068924e-003,0.000000e+000,0,1,0,
1652373082.984,,1.800000e+004,1.999876e+001,1.932008e-001,5.731971e-005,3,9.921209e-001,2.966847e-002,,,,,,,,,,,,,,32,2,4.000000e+000,5.529404e-003,0.000000e+000,0,1,0,
1652373270.906,,2.000000e+004,1.999769e+001,2.130344e-001,6.811984e-005,3,9.920173e-001,3.197598e-002,,,,,,,,,,,,,,32,2,4.000000e+000,3.070831e-003,0.000000e+000,0,0,0,
1652373457.531,,2.200000e+004,1.999953e+001,2.325659e-001,9.789659e-005,3,9.920982e-001,4.209413e-002,,,,,,,,,,,,,,32,2,4.000000e+000,1.838684e-003,0.000000e+000,0,0,0,
1652373650.468,,2.400000e+004,1.999815e+001,2.520141e-001,1.353125e-004,3,9.917547e-001,5.369242e-002,,,,,,,,,,,,,,32,2,4.000000e+000,2.449036e-003,0.000000e+000,0,0,0,
1652373840.562,,2.600000e+004,2.000214e+001,2.710890e-001,1.983220e-004,3,9.919817e-001,7.315752e-002,,,,,,,,,,,,,,32,2,4.000000e+000,1.840591e-003,0.000000e+000,0,1,0,
1652374024.828,,2.800000e+004,1.999999e+001,2.899813e-001,1.184959e-004,3,9.921063e-001,4.086328e-002,,,,,,,,,,,,,,32,2,4.000000e+000,1.840591e-003,0.000000e+000,0,1,0,
1652374218.000,,3.000000e+004,1.999922e+001,3.088385e-001,1.479354e-004,3,9.920510e-001,4.790058e-002,,,,,,,,,,,,,,32,2,4.000000e+000,4.909515e-003,0.000000e+000,0,1,0,
1652374407.359,,3.200000e+004,1.999923e+001,3.274556e-001,1.164096e-004,3,9.921236e-001,3.554973e-002,,,,,,,,,,,,,,32,2,4.000000e+000,5.519867e-003,0.000000e+000,0,1,0,
1652374599.421,,3.400000e+004,1.999800e+001,3.460346e-001,2.280987e-004,3,9.919309e-001,6.591790e-002,,,,,,,,,,,,,,32,2,4.000000e+000,6.198883e-004,0.000000e+000,0,0,0,
1652374794.609,,3.600000e+004,1.999769e+001,3.644119e-001,1.258085e-005,3,9.920838e-001,3.452371e-003,,,,,,,,,,,,,,32,2,4.000000e+000,1.230240e-003,0.000000e+000,0,0,0,
1652374986.671,,3.800000e+004,2.000060e+001,3.825285e-001,2.368231e-004,3,9.919536e-001,6.190993e-002,,,,,,,,,,,,,,32,2,4.000000e+000,7.369995e-003,0.000000e+000,0,1,0,
1652375179.500,,4.000000e+004,1.999937e+001,4.005955e-001,2.285202e-004,3,9.919478e-001,5.704513e-002,,,,,,,,,,,,,,32,2,4.000000e+000,1.218796e-003,0.000000e+000,0,1,0,
1652375375.500,,4.200000e+004,1.999999e+001,4.185131e-001,1.794402e-004,3,9.920316e-001,4.287565e-002,,,,,,,,,,,,,,32,2,4.000000e+000,3.070831e-003,0.000000e+000,0,1,0,
1652375568.203,,4.400000e+004,2.000014e+001,4.363405e-001,1.911360e-004,3,9.920186e-001,4.380431e-002,,,,,,,,,,,,,,32,2,4.000000e+000,3.688812e-003,0.000000e+000,0,1,0,
1652375762.093,,4.600000e+004,2.000045e+001,4.540794e-001,2.085005e-004,3,9.919964e-001,4.591718e-002,,,,,,,,,,,,,,32,2,4.000000e+000,1.840591e-003,0.000000e+000,0,1,0,
1652375952.750,,4.800000e+004,1.999999e+001,4.718069e-001,1.478933e-004,3,9.919899e-001,3.134615e-002,,,,,,,,,,,,,,32,2,4.000000e+000,4.919052e-003,0.000000e+000,0,1,0,
1652376156.515,,5.000000e+004,1.999784e+001,4.893404e-001,2.034007e-004,3,9.920912e-001,4.156630e-002,,,,,,,,,,,,,,32,2,4.000000e+000,1.850128e-003,0.000000e+000,0,0,0,
1652384204.765,,0.000000e+000,2.999766e+001,-3.483781e-004,2.463369e-008,3,9.916940e-001,7.070964e-003,,,,,,,,,,,,,,32,2,4.000000e+000,9.880066e-003,0.000000e+000,0,1,0,
1652384342.750,,2.000000e+002,3.000136e+001,1.747288e-003,6.694105e-007,3,9.934752e-001,3.831140e-002,,,,,,,,,,,,,,32,2,4.000000e+000,6.168365e-003,0.000000e+000,0,1,0,
1652384459.968,,4.000000e+002,3.000074e+001,3.925215e-003,1.381297e-006,3,9.930105e-001,3.519035e-002,,,,,,,,,,,,,,32,2,4.000000e+000,3.698349e-003,0.000000e+000,0,1,0,
1652384607.265,,6.000000e+002,2.999734e+001,6.168820e-003,4.919327e-007,3,9.931403e-001,7.974503e-003,,,,,,,,,,,,,,32,2,4.000000e+000,1.236153e-002,0.000000e+000,0,1,0,
1652384724.343,,8.000000e+002,2.999611e+001,8.814825e-003,1.407310e-006,3,9.929349e-001,1.596526e-002,,,,,,,,,,,,,,32,2,4.000000e+000,2.470016e-003,0.000000e+000,0,0,0,
1652384842.125,,1.000000e+003,2.999920e+001,1.123624e-002,3.831412e-006,3,9.927613e-001,3.409869e-002,,,,,,,,,,,,,,32,2,4.000000e+000,7.410049e-003,0.000000e+000,0,0,0,
1652384959.218,,1.200000e+003,2.999487e+001,1.342528e-002,4.248139e-005,3,9.934418e-001,3.164282e-001,,,,,,,,,,,,,,32,2,4.000000e+000,7.421494e-003,0.000000e+000,0,0,0,
1652385076.546,,1.400000e+003,2.999704e+001,1.565564e-002,3.648360e-007,3,9.927723e-001,2.330381e-003,,,,,,,,,,,,,,32,2,4.000000e+000,4.940033e-003,0.000000e+000,0,0,0,
1652385212.515,,1.600000e+003,2.999827e+001,1.784652e-002,1.580507e-007,3,9.928507e-001,8.856109e-004,,,,,,,,,,,,,,32,2,4.000000e+000,4.940033e-003,0.000000e+000,0,0,0,
1652385335.250,,1.800000e+003,2.999642e+001,2.005280e-002,4.886418e-007,3,9.926053e-001,2.436776e-003,,,,,,,,,,,,,,32,2,4.000000e+000,7.421494e-003,0.000000e+000,0,0,0,
1652385453.375,,2.000000e+003,2.999981e+001,2.222703e-002,5.504115e-006,3,9.926662e-001,2.476316e-002,,,,,,,,,,,,,,32,2,4.000000e+000,3.711700e-003,0.000000e+000,0,1,0,
1652385570.906,,2.200000e+003,3.000043e+001,2.442626e-002,1.028647e-006,3,9.927015e-001,4.211235e-003,,,,,,,,,,,,,,32,2,4.000000e+000,2.470016e-003,0.000000e+000,0,1,0,
1652385691.734,,2.400000e+003,3.000105e+001,2.662751e-002,5.623986e-007,3,9.927267e-001,2.112096e-003,,,,,,,,,,,,,,32,2,4.000000e+000,3.698349e-003,0.000000e+000,0,1,0,
1652385814.859,,2.600000e+003,3.000074e+001,2.884100e-002,9.404015e-007,3,9.927311e-001,3.260641e-003,,,,,,,,,,,,,,32,2,4.000000e+000,9.880066e-003,0.000000e+000,0,1,0,
1652385938.546,,2.800000e+003,2.999858e+001,3.104557e-002,1.975633e-006,3,9.927037e-001,6.363658e-003,,,,,,,,,,,,,,32,2,4.000000e+000,4.940033e-003,0.000000e+000,0,1,0,
1652386057.234,,3.000000e+003,2.999456e+001,3.325225e-002,2.473495e-006,3,9.926964e-001,7.438579e-003,,,,,,,,,,,,,,32,2,4.000000e+000,7.421494e-003,0.000000e+000,0,0,0,
1652386181.156,,3.200000e+003,2.999487e+001,3.547471e-002,6.912083e-006,3,9.926822e-001,1.948454e-002,,,,,,,,,,,,,,32,2,4.000000e+000,7.421494e-003,0.000000e+000,0,0,0,
1652386306.843,,3.400000e+003,2.999827e+001,3.767727e-002,2.631545e-006,3,9.926846e-001,6.984438e-003,,,,,,,,,,,,,,32,2,4.000000e+000,7.410049e-003,0.000000e+000,0,0,0,
1652386430.218,,3.600000e+003,2.999765e+001,3.988369e-002,3.226869e-006,3,9.926675e-001,8.090699e-003,,,,,,,,,,,,,,32,2,4.000000e+000,6.168365e-003,0.000000e+000,0,0,0,
1652386548.375,,3.800000e+003,2.999858e+001,4.207828e-002,2.734277e-006,3,9.926407e-001,6.498072e-003,,,,,,,,,,,,,,32,2,4.000000e+000,2.470016e-003,0.000000e+000,0,0,0,
1652386671.765,,4.000000e+003,2.999889e+001,4.428544e-002,1.891340e-006,3,9.925668e-001,4.270793e-003,,,,,,,,,,,,,,32,2,4.000000e+000,8.638382e-003,0.000000e+000,0,0,0,
1652386803.500,,4.200000e+003,2.999703e+001,4.637713e-002,1.262087e-004,3,9.926558e-001,2.721357e-001,,,,,,,,,,,,,,32,2,4.000000e+000,6.168365e-003,0.000000e+000,0,1,0,
1652386926.515,,4.400000e+003,2.999673e+001,4.864699e-002,2.315444e-006,3,9.926407e-001,4.759686e-003,,,,,,,,,,,,,,32,2,4.000000e+000,8.651733e-003,0.000000e+000,0,1,0,
1652387050.640,,4.600000e+003,2.999827e+001,5.081126e-002,4.644057e-006,3,9.926278e-001,9.139818e-003,,,,,,,,,,,,,,32,2,4.000000e+000,1.112175e-002,0.000000e+000,0,1,0,
1652387169.421,,4.800000e+003,2.999827e+001,5.295701e-002,3.648337e-006,3,9.925828e-001,6.889243e-003,,,,,,,,,,,,,,32,2,4.000000e+000,3.709793e-003,0.000000e+000,0,1,0,
1652387292.156,,5.000000e+003,2.999734e+001,5.514459e-002,3.835100e-005,3,9.927855e-001,6.954626e-002,,,,,,,,,,,,,,32,2,4.000000e+000,4.940033e-003,0.000000e+000,0,1,0,
1652387421.109,,6.000000e+003,2.999827e+001,6.569488e-002,5.452751e-006,3,9.925431e-001,8.300115e-003,,,,,,,,,,,,,,32,2,4.000000e+000,8.651733e-003,0.000000e+000,0,0,0,
1652387542.578,,6.500000e+003,2.999765e+001,7.091947e-002,1.614751e-005,3,9.925115e-001,2.276880e-002,,,,,,,,,,,,,,32,2,4.000000e+000,3.711700e-003,0.000000e+000,0,0,0,
1652387670.437,,7.000000e+003,2.999796e+001,7.610773e-002,5.157723e-006,3,9.925369e-001,6.776872e-003,,,,,,,,,,,,,,32,2,4.000000e+000,2.481461e-003,0.000000e+000,0,0,0,
1652387801.406,,7.500000e+003,2.999642e+001,8.123554e-002,7.654923e-006,3,9.925388e-001,9.423121e-003,,,,,,,,,,,,,,32,2,4.000000e+000,7.410049e-003,0.000000e+000,0,0,0,
1652387928.281,,8.000000e+003,2.999858e+001,8.632921e-002,9.240696e-006,3,9.925764e-001,1.070402e-002,,,,,,,,,,,,,,32,2,4.000000e+000,4.951477e-003,0.000000e+000,0,0,0,
1652388071.250,,8.500000e+003,2.999981e+001,9.136454e-002,5.247283e-006,3,9.927465e-001,5.743238e-003,,,,,,,,,,,,,,32,2,4.000000e+000,7.421494e-003,0.000000e+000,0,0,0,
1652388199.406,,9.000000e+003,2.999920e+001,9.639027e-002,1.842871e-005,3,9.924938e-001,1.911885e-002,,,,,,,,,,,,,,32,2,4.000000e+000,9.880066e-003,0.000000e+000,0,1,0,
1652388326.859,,9.500000e+003,3.000136e+001,1.013542e-001,2.654725e-005,3,9.925043e-001,2.619254e-002,,,,,,,,,,,,,,32,2,4.000000e+000,6.181717e-003,0.000000e+000,0,1,0,
1652388454.250,,1.000000e+004,2.999796e+001,1.063009e-001,2.404478e-005,3,9.925137e-001,2.261954e-002,,,,,,,,,,,,,,32,2,4.000000e+000,4.940033e-003,0.000000e+000,0,1,0,
1652388584.453,,1.200000e+004,2.999981e+001,1.258376e-001,2.739545e-005,3,9.924855e-001,2.177048e-002,,,,,,,,,,,,,,32,2,4.000000e+000,3.711700e-003,0.000000e+000,0,1,0,
1652388718.796,,1.400000e+004,2.999703e+001,1.451217e-001,2.481396e-005,3,9.923378e-001,1.709873e-002,,,,,,,,,,,,,,32,2,4.000000e+000,3.711700e-003,0.000000e+000,0,1,0,
1652388852.953,,1.600000e+004,2.999827e+001,1.642682e-001,3.171550e-005,3,9.924728e-001,1.930715e-002,,,,,,,,,,,,,,32,2,4.000000e+000,4.940033e-003,0.000000e+000,0,0,0,
1652389001.859,,1.800000e+004,2.999981e+001,1.831749e-001,1.692196e-005,3,9.927137e-001,9.238144e-003,,,,,,,,,,,,,,32,2,4.000000e+000,6.179810e-003,0.000000e+000,0,0,0,
1652389138.937,,2.000000e+004,2.999889e+001,2.020410e-001,4.670925e-005,3,9.924256e-001,2.311870e-002,,,,,,,,,,,,,,32,2,4.000000e+000,8.651733e-003,0.000000e+000,0,0,0,
1652389271.578,,2.200000e+004,2.999889e+001,2.207242e-001,5.392689e-005,3,9.923737e-001,2.443180e-002,,,,,,,,,,,,,,32,2,4.000000e+000,3.711700e-003,0.000000e+000,0,0,0,
1652389407.625,,2.400000e+004,3.000167e+001,2.392514e-001,4.823707e-005,3,9.924271e-001,2.016166e-002,,,,,,,,,,,,,,32,2,4.000000e+000,0.000000e+000,0.000000e+000,0,1,0,
1652389545.718,,2.600000e+004,2.999920e+001,2.576798e-001,6.117616e-005,3,9.924203e-001,2.374115e-002,,,,,,,,,,,,,,32,2,4.000000e+000,7.410049e-003,0.000000e+000,0,1,0,
1652389678.546,,2.800000e+004,2.999920e+001,2.759736e-001,5.578136e-005,3,9.923801e-001,2.021257e-002,,,,,,,,,,,,,,32,2,4.000000e+000,2.470016e-003,0.000000e+000,0,1,0,
1652389817.281,,3.000000e+004,2.999827e+001,2.941745e-001,6.918405e-005,3,9.923478e-001,2.351803e-002,,,,,,,,,,,,,,32,2,4.000000e+000,6.181717e-003,0.000000e+000,0,1,0,
1652389952.203,,3.200000e+004,2.999981e+001,3.122615e-001,7.967862e-005,3,9.923911e-001,2.551663e-002,,,,,,,,,,,,,,32,2,4.000000e+000,2.470016e-003,0.000000e+000,0,1,0,
1652390087.312,,3.400000e+004,2.999920e+001,3.302326e-001,6.652880e-005,3,9.924064e-001,2.014604e-002,,,,,,,,,,,,,,32,2,4.000000e+000,4.951477e-003,0.000000e+000,0,1,0,
1652390222.671,,3.600000e+004,2.999951e+001,3.481262e-001,7.070134e-005,3,9.923722e-001,2.030911e-002,,,,,,,,,,,,,,32,2,4.000000e+000,8.638382e-003,0.000000e+000,0,1,0,
1652390358.421,,3.800000e+004,2.999673e+001,3.659287e-001,9.729600e-005,3,9.923592e-001,2.658879e-002,,,,,,,,,,,,,,32,2,4.000000e+000,3.711700e-003,0.000000e+000,0,0,0,
1652390501.671,,4.000000e+004,2.999796e+001,3.836154e-001,5.957457e-005,3,9.923996e-001,1.552977e-002,,,,,,,,,,,,,,32,2,4.000000e+000,3.711700e-003,0.000000e+000,0,0,0,
1652390644.046,,4.200000e+004,3.000043e+001,4.012318e-001,9.120578e-005,3,9.924181e-001,2.273144e-002,,,,,,,,,,,,,,32,2,4.000000e+000,3.698349e-003,0.000000e+000,0,1,0,
1652390785.718,,4.400000e+004,2.999858e+001,4.187500e-001,6.486400e-005,3,9.923948e-001,1.548991e-002,,,,,,,,,,,,,,32,2,4.000000e+000,2.470016e-003,0.000000e+000,0,1,0,
1652390918.421,,4.600000e+004,2.999920e+001,4.362515e-001,8.191240e-005,3,9.923896e-001,1.877642e-002,,,,,,,,,,,,,,32,2,4.000000e+000,4.940033e-003,0.000000e+000,0,1,0,
1652391125.281,,4.800000e+004,2.999796e+001,4.539827e-001,1.322779e-004,3,9.918764e-001,2.913721e-002,,,,,,,,,,,,,,32,2,4.000000e+000,7.410049e-003,0.000000e+000,0,1,0,
1652391322.281,,5.000000e+004,2.999796e+001,4.713955e-001,1.954139e-004,3,9.919317e-001,4.145433e-002,,,,,,,,,,,,,,32,2,4.000000e+000,2.481461e-003,0.000000e+000,0,1,0,
1652399217.296,,0.000000e+000,4.000154e+001,-3.900245e-004,3.557169e-007,3,9.917495e-001,9.120374e-002,,,,,,,,,,,,,,32,2,4.000000e+000,1.414871e-002,0.000000e+000,0,1,0,
1652399350.078,,2.000000e+002,3.999952e+001,1.635092e-003,3.155251e-007,3,9.935607e-001,1.929708e-002,,,,,,,,,,,,,,32,2,4.000000e+000,1.009750e-002,0.000000e+000,0,1,0,
1652399472.328,,4.000000e+002,3.999345e+001,3.766117e-003,1.127428e-006,3,9.929295e-001,2.993609e-002,,,,,,,,,,,,,,32,2,4.000000e+000,1.211929e-002,0.000000e+000,0,0,0,
1652399623.281,,6.000000e+002,4.000053e+001,5.971231e-003,1.127099e-006,3,9.931546e-001,1.887549e-002,,,,,,,,,,,,,,32,2,4.000000e+000,1.010895e-002,0.000000e+000,0,0,0,
1652399742.375,,8.000000e+002,3.999952e+001,8.638158e-003,1.106355e-007,3,9.930518e-001,1.280776e-003,,,,,,,,,,,,,,32,2,4.000000e+000,1.414871e-002,0.000000e+000,0,0,0,
1652399859.515,,1.000000e+003,3.999446e+001,1.092658e-002,1.361146e-005,3,9.928529e-001,1.245720e-001,,,,,,,,,,,,,,32,2,4.000000e+000,6.057739e-003,0.000000e+000,0,0,0,
1652399977.984,,1.200000e+003,3.999548e+001,1.308434e-002,1.570497e-005,3,9.930853e-001,1.200287e-001,,,,,,,,,,,,,,32,2,4.000000e+000,4.039764e-003,0.000000e+000,0,0,0,
1652400096.421,,1.400000e+003,3.999800e+001,1.523136e-002,1.044847e-005,3,9.929091e-001,6.859837e-002,,,,,,,,,,,,,,32,2,4.000000e+000,6.057739e-003,0.000000e+000,0,0,0,
1652400214.453,,1.600000e+003,3.999952e+001,1.735783e-002,1.408100e-005,3,9.928422e-001,8.112187e-002,,,,,,,,,,,,,,32,2,4.000000e+000,2.017975e-003,0.000000e+000,0,0,0,
1652400367.046,,1.800000e+003,4.000103e+001,1.951896e-002,1.267040e-006,3,9.931775e-001,6.491329e-003,,,,,,,,,,,,,,32,2,4.000000e+000,2.029419e-003,0.000000e+000,0,1,0,
1652400490.015,,2.000000e+003,3.999902e+001,2.165121e-002,3.055647e-006,3,9.928330e-001,1.411305e-002,,,,,,,,,,,,,,32,2,4.000000e+000,1.617050e-002,0.000000e+000,0,1,0,
1652400613.937,,2.200000e+003,4.000204e+001,2.380947e-002,1.699096e-007,3,9.926988e-001,7.136220e-004,,,,,,,,,,,,,,32,2,4.000000e+000,1.617050e-002,0.000000e+000,0,1,0,
1652400737.484,,2.400000e+003,3.999295e+001,2.591166e-002,5.177740e-005,3,9.922318e-001,1.998228e-001,,,,,,,,,,,,,,32,2,4.000000e+000,1.010132e-002,0.000000e+000,0,1,0,
1652400858.859,,2.600000e+003,3.999648e+001,2.809954e-002,2.178465e-006,3,9.926938e-001,7.752673e-003,,,,,,,,,,,,,,32,2,4.000000e+000,2.021790e-003,0.000000e+000,0,0,0,
1652400983.515,,2.800000e+003,4.000002e+001,3.023977e-002,4.860077e-007,3,9.927189e-001,1.607180e-003,,,,,,,,,,,,,,32,2,4.000000e+000,8.079529e-003,0.000000e+000,0,0,0,
1652401102.046,,3.000000e+003,3.999952e+001,3.237719e-002,1.633190e-007,3,9.926777e-001,5.044262e-004,,,,,,,,,,,,,,32,2,4.000000e+000,4.047394e-003,0.000000e+000,0,0,0,
1652401223.125,,3.200000e+003,4.000002e+001,3.452327e-002,1.896608e-007,3,9.927028e-001,5.493709e-004,,,,,,,,,,,,,,32,2,4.000000e+000,1.009750e-002,0.000000e+000,0,0,0,
1652401346.281,,3.400000e+003,3.999447e+001,3.664789e-002,1.390846e-006,3,9.926687e-001,3.795160e-003,,,,,,,,,,,,,,32,2,4.000000e+000,1.212692e-002,0.000000e+000,0,0,0,
1652401471.265,,3.600000e+003,3.999497e+001,3.876970e-002,1.409288e-006,3,9.926499e-001,3.635024e-003,,,,,,,,,,,,,,32,2,4.000000e+000,8.079529e-003,0.000000e+000,0,0,0,
1652401594.921,,3.800000e+003,4.000002e+001,4.088757e-002,4.003951e-007,3,9.925967e-001,9.792587e-004,,,,,,,,,,,,,,32,2,4.000000e+000,8.079529e-003,0.000000e+000,0,0,0,
1652401717.093,,4.000000e+003,3.999850e+001,4.297127e-002,1.733289e-006,3,9.926451e-001,4.033600e-003,,,,,,,,,,,,,,32,2,4.000000e+000,2.017975e-003,0.000000e+000,0,1,0,
1652401852.031,,4.200000e+003,3.999901e+001,4.504455e-002,2.984525e-006,3,9.929554e-001,6.625718e-003,,,,,,,,,,,,,,32,2,4.000000e+000,2.017975e-003,0.000000e+000,0,1,0,
1652401974.593,,4.400000e+003,4.000204e+001,4.712293e-002,6.640763e-006,3,9.927028e-001,1.409243e-002,,,,,,,,,,,,,,32,2,4.000000e+000,8.079529e-003,0.000000e+000,0,1,0,
1652402094.109,,4.600000e+003,3.999598e+001,4.918114e-002,6.169245e-006,3,9.926298e-001,1.254392e-002,,,,,,,,,,,,,,32,2,4.000000e+000,4.039764e-003,0.000000e+000,0,1,0,
1652402214.531,,4.800000e+003,3.999901e+001,5.121738e-002,6.632860e-006,3,9.925936e-001,1.295041e-002,,,,,,,,,,,,,,32,2,4.000000e+000,4.047394e-003,0.000000e+000,0,0,0,
1652402335.953,,5.000000e+003,3.999750e+001,5.326099e-002,1.003358e-005,3,9.926044e-001,1.883852e-002,,,,,,,,,,,,,,32,2,4.000000e+000,1.212692e-002,0.000000e+000,0,0,0,
1652402465.937,,6.000000e+003,3.999649e+001,6.326404e-002,1.042608e-005,3,9.926035e-001,1.648026e-002,,,,,,,,,,,,,,32,2,4.000000e+000,8.079529e-003,0.000000e+000,0,0,0,
1652402590.140,,6.500000e+003,4.000002e+001,6.818423e-002,8.039511e-006,3,9.926074e-001,1.179087e-002,,,,,,,,,,,,,,32,2,4.000000e+000,8.079529e-003,0.000000e+000,0,0,0,
1652402716.000,,7.000000e+003,3.999648e+001,7.306372e-002,8.640104e-006,3,9.925778e-001,1.182544e-002,,,,,,,,,,,,,,32,2,4.000000e+000,2.021790e-003,0.000000e+000,0,0,0,
1652402839.328,,7.500000e+003,3.999800e+001,7.787506e-002,9.714849e-006,3,9.925693e-001,1.247492e-002,,,,,,,,,,,,,,32,2,4.000000e+000,6.069183e-003,0.000000e+000,0,0,0,
1652402966.156,,8.000000e+003,3.999800e+001,8.265723e-002,1.259137e-005,3,9.924729e-001,1.523324e-002,,,,,,,,,,,,,,32,2,4.000000e+000,4.039764e-003,0.000000e+000,0,0,0,
1652403091.796,,8.500000e+003,3.999750e+001,8.740421e-002,1.408758e-005,3,9.925292e-001,1.611774e-002,,,,,,,,,,,,,,32,2,4.000000e+000,4.039764e-003,0.000000e+000,0,1,0,
1652403234.671,,9.000000e+003,4.000305e+001,9.210099e-002,1.036286e-005,3,9.927630e-001,1.125162e-002,,,,,,,,,,,,,,32,2,4.000000e+000,6.069183e-003,0.000000e+000,0,1,0,
1652403362.734,,9.500000e+003,4.000053e+001,9.680346e-002,2.667896e-005,3,9.924701e-001,2.755992e-002,,,,,,,,,,,,,,32,2,4.000000e+000,6.069183e-003,0.000000e+000,0,1,0,
1652403491.093,,1.000000e+004,3.999750e+001,1.014621e-001,1.364504e-005,3,9.925250e-001,1.344842e-002,,,,,,,,,,,,,,32,2,4.000000e+000,1.010895e-002,0.000000e+000,0,1,0,
1652403626.156,,1.200000e+004,3.999800e+001,1.199933e-001,2.671062e-006,3,9.925524e-001,2.226008e-003,,,,,,,,,,,,,,32,2,4.000000e+000,8.079529e-003,0.000000e+000,0,1,0,
1652403753.859,,1.400000e+004,3.999548e+001,1.383162e-001,3.233717e-005,3,9.924295e-001,2.337917e-002,,,,,,,,,,,,,,32,2,4.000000e+000,4.039764e-003,0.000000e+000,0,0,0,
1652403885.500,,1.600000e+004,3.999598e+001,1.565374e-001,4.493908e-005,3,9.923608e-001,2.870821e-002,,,,,,,,,,,,,,32,2,4.000000e+000,6.057739e-003,0.000000e+000,0,0,0,
1652404014.828,,1.800000e+004,3.999851e+001,1.746124e-001,4.382219e-005,3,9.923540e-001,2.509684e-002,,,,,,,,,,,,,,32,2,4.000000e+000,6.069183e-003,0.000000e+000,0,0,0,
1652404221.046,,2.000000e+004,3.999800e+001,1.927257e-001,4.908000e-005,3,9.916990e-001,2.546625e-002,,,,,,,,,,,,,,32,2,4.000000e+000,4.039764e-003,0.000000e+000,0,0,0,
1652404420.390,,2.200000e+004,4.000002e+001,2.106107e-001,1.448587e-004,3,9.918096e-001,6.878032e-002,,,,,,,,,,,,,,32,2,4.000000e+000,0.000000e+000,0.000000e+000,0,1,0,
1652404610.203,,2.400000e+004,3.999850e+001,2.284171e-001,1.690405e-004,3,9.917912e-001,7.400519e-002,,,,,,,,,,,,,,32,2,4.000000e+000,4.039764e-003,0.000000e+000,0,1,0,
1652404797.906,,2.600000e+004,3.999850e+001,2.460909e-001,1.387053e-004,3,9.918929e-001,5.636343e-002,,,,,,,,,,,,,,32,2,4.000000e+000,2.017975e-003,0.000000e+000,0,1,0,
1652404990.500,,2.800000e+004,3.999800e+001,2.637327e-001,9.546261e-005,3,9.917579e-001,3.619673e-002,,,,,,,,,,,,,,32,2,4.000000e+000,4.039764e-003,0.000000e+000,0,1,0,
1652405190.828,,3.000000e+004,3.999699e+001,2.814211e-001,2.135159e-004,3,9.916883e-001,7.587061e-002,,,,,,,,,,,,,,32,2,4.000000e+000,2.021790e-003,0.000000e+000,0,0,0,
1652405389.468,,3.200000e+004,3.999800e+001,2.988783e-001,1.498953e-004,3,9.919536e-001,5.015261e-002,,,,,,,,,,,,,,32,2,4.000000e+000,0.000000e+000,0.000000e+000,0,0,0,
1652405576.671,,3.400000e+004,3.999749e+001,3.162464e-001,2.083108e-004,3,9.919178e-001,6.586978e-002,,,,,,,,,,,,,,32,2,4.000000e+000,4.039764e-003,0.000000e+000,0,1,0,
1652405766.750,,3.600000e+004,3.999800e+001,3.335475e-001,1.671755e-004,3,9.919640e-001,5.012044e-002,,,,,,,,,,,,,,32,2,4.000000e+000,4.039764e-003,0.000000e+000,0,1,0,
1652405951.843,,3.800000e+004,3.999851e+001,3.508914e-001,2.489825e-004,3,9.918669e-001,7.095715e-002,,,,,,,,,,,,,,32,2,4.000000e+000,6.069183e-003,0.000000e+000,0,1,0,
1652406145.203,,4.000000e+004,3.999850e+001,3.680836e-001,1.186855e-004,3,9.917986e-001,3.224418e-002,,,,,,,,,,,,,,32,2,4.000000e+000,4.039764e-003,0.000000e+000,0,1,0,
1652406338.703,,4.200000e+004,3.999901e+001,3.853183e-001,2.008297e-004,3,9.919451e-001,5.212047e-002,,,,,,,,,,,,,,32,2,4.000000e+000,2.017975e-003,0.000000e+000,0,1,0,
1652406531.640,,4.400000e+004,3.999750e+001,4.025633e-001,2.517431e-004,3,9.918113e-001,6.253504e-002,,,,,,,,,,,,,,32,2,4.000000e+000,1.009750e-002,0.000000e+000,0,0,0,
1652406741.109,,4.600000e+004,3.999800e+001,4.196799e-001,2.171616e-004,3,9.920171e-001,5.174459e-002,,,,,,,,,,,,,,32,2,4.000000e+000,4.039764e-003,0.000000e+000,0,1,0,
1652406931.875,,4.800000e+004,3.999952e+001,4.366021e-001,1.551847e-004,3,9.919380e-001,3.554373e-002,,,,,,,,,,,,,,32,2,4.000000e+000,4.047394e-003,0.000000e+000,0,1,0,
1652407130.390,,5.000000e+004,3.999952e+001,4.537148e-001,3.249944e-004,3,9.918637e-001,7.162965e-002,,,,,,,,,,,,,,32,2,4.000000e+000,2.017975e-003,0.000000e+000,0,1,0,
1652414757.312,,0.000000e+000,4.999954e+001,-2.338996e-004,3.712545e-008,3,9.901430e-001,1.587239e-002,,,,,,,,,,,,,,32,2,4.000000e+000,7.152557e-003,0.000000e+000,0,1,0,
1652414896.406,,2.000000e+002,5.000460e+001,1.744482e-003,6.206782e-007,3,9.935737e-001,3.557952e-002,,,,,,,,,,,,,,32,2,4.000000e+000,5.958557e-003,0.000000e+000,0,1,0,
1652415017.484,,4.000000e+002,5.000073e+001,3.816685e-003,4.734935e-007,3,9.929868e-001,1.240589e-002,,,,,,,,,,,,,,32,2,4.000000e+000,5.962372e-003,0.000000e+000,0,1,0,
1652415169.984,,6.000000e+002,5.000013e+001,5.986071e-003,1.113928e-006,3,9.931960e-001,1.860867e-002,,,,,,,,,,,,,,32,2,4.000000e+000,8.342743e-003,0.000000e+000,0,0,0,
1652415289.281,,8.000000e+002,4.999566e+001,8.587183e-003,1.748436e-006,3,9.929020e-001,2.036099e-002,,,,,,,,,,,,,,32,2,4.000000e+000,1.549911e-002,0.000000e+000,0,0,0,
1652415411.453,,1.000000e+003,4.999685e+001,1.077267e-002,2.270662e-006,3,9.929286e-001,2.107799e-002,,,,,,,,,,,,,,32,2,4.000000e+000,5.958557e-003,0.000000e+000,0,0,0,
1652415530.015,,1.200000e+003,4.999715e+001,1.288193e-002,1.487915e-005,3,9.924747e-001,1.155041e-001,,,,,,,,,,,,,,32,2,4.000000e+000,5.958557e-003,0.000000e+000,0,0,0,
1652415645.187,,1.400000e+003,4.999864e+001,1.498395e-002,3.689825e-006,3,9.931423e-001,2.462518e-002,,,,,,,,,,,,,,32,2,4.000000e+000,1.072693e-002,0.000000e+000,0,0,0,
1652415768.312,,1.600000e+003,4.999596e+001,1.710963e-002,1.349489e-005,3,9.927784e-001,7.887310e-002,,,,,,,,,,,,,,32,2,4.000000e+000,1.311111e-002,0.000000e+000,0,0,0,
1652415918.656,,1.800000e+003,5.000251e+001,1.923153e-002,1.191966e-005,3,9.928614e-001,6.197974e-002,,,,,,,,,,,,,,32,2,4.000000e+000,1.191711e-002,0.000000e+000,0,1,0,
1652416035.484,,2.000000e+003,4.999625e+001,2.130866e-002,3.312479e-006,3,9.927575e-001,1.554522e-002,,,,,,,,,,,,,,32,2,4.000000e+000,1.193237e-002,0.000000e+000,0,1,0,
1652416154.375,,2.200000e+003,4.999656e+001,2.341643e-002,6.773789e-006,3,9.927077e-001,2.892751e-002,,,,,,,,,,,,,,32,2,4.000000e+000,9.540558e-003,0.000000e+000,0,1,0,
1652416271.562,,2.400000e+003,4.999924e+001,2.552823e-002,2.208759e-006,3,9.926316e-001,8.652219e-003,,,,,,,,,,,,,,32,2,4.000000e+000,4.772186e-003,0.000000e+000,0,1,0,
1652416393.203,,2.600000e+003,4.999834e+001,2.763418e-002,4.464951e-007,3,9.926435e-001,1.615735e-003,,,,,,,,,,,,,,32,2,4.000000e+000,1.549911e-002,0.000000e+000,0,1,0,
1652416516.203,,2.800000e+003,4.999566e+001,2.972341e-002,3.573263e-006,3,9.925699e-001,1.202171e-002,,,,,,,,,,,,,,32,2,4.000000e+000,3.578186e-003,0.000000e+000,0,0,0,
1652416635.171,,3.000000e+003,4.999745e+001,3.179243e-002,5.974316e-006,3,9.926443e-001,1.879163e-002,,,,,,,,,,,,,,32,2,4.000000e+000,1.787949e-002,0.000000e+000,0,0,0,
1652416755.875,,3.200000e+003,4.999656e+001,3.387103e-002,2.086269e-006,3,9.925771e-001,6.159450e-003,,,,,,,,,,,,,,32,2,4.000000e+000,7.148743e-003,0.000000e+000,0,0,0,
1652416880.421,,3.400000e+003,4.999864e+001,3.591458e-002,2.426079e-006,3,9.926689e-001,6.755137e-003,,,,,,,,,,,,,,32,2,4.000000e+000,1.789093e-002,0.000000e+000,0,0,0,
1652417003.703,,3.600000e+003,4.999297e+001,3.794853e-002,8.324002e-007,3,9.925969e-001,2.193498e-003,,,,,,,,,,,,,,32,2,4.000000e+000,4.772186e-003,0.000000e+000,0,0,0,
1652417126.796,,3.800000e+003,4.999358e+001,3.997932e-002,1.638459e-006,3,9.925560e-001,4.098265e-003,,,,,,,,,,,,,,32,2,4.000000e+000,1.311111e-002,0.000000e+000,0,0,0,
1652417248.093,,4.000000e+003,4.999984e+001,4.197612e-002,3.516629e-006,3,9.925885e-001,8.377688e-003,,,,,,,,,,,,,,32,2,4.000000e+000,5.962372e-003,0.000000e+000,0,1,0,
1652417365.890,,4.200000e+003,4.999685e+001,4.395673e-002,1.533092e-006,3,9.925995e-001,3.487729e-003,,,,,,,,,,,,,,32,2,4.000000e+000,1.074219e-002,0.000000e+000,0,1,0,
1652417500.750,,4.400000e+003,4.999924e+001,4.593053e-002,1.335531e-006,3,9.928923e-001,2.907719e-003,,,,,,,,,,,,,,32,2,4.000000e+000,1.549911e-002,0.000000e+000,0,1,0,
1652417625.265,,4.600000e+003,4.999626e+001,4.790087e-002,8.727032e-006,3,9.924750e-001,1.821894e-002,,,,,,,,,,,,,,32,2,4.000000e+000,2.027130e-002,0.000000e+000,0,1,0,
1652417747.687,,4.800000e+003,4.999357e+001,4.976493e-002,1.314982e-004,3,9.924802e-001,2.642386e-001,,,,,,,,,,,,,,32,2,4.000000e+000,4.772186e-003,0.000000e+000,0,1,0,
1652417872.250,,5.000000e+003,5.000341e+001,5.178363e-002,1.044188e-005,3,9.924669e-001,2.016445e-002,,,,,,,,,,,,,,32,2,4.000000e+000,9.540558e-003,0.000000e+000,0,0,0,
1652417998.875,,6.000000e+003,4.999626e+001,6.127315e-002,1.514916e-005,3,9.924570e-001,2.472397e-002,,,,,,,,,,,,,,32,2,4.000000e+000,4.768372e-003,0.000000e+000,0,0,0,
1652418125.281,,6.500000e+003,4.999775e+001,6.593066e-002,1.414027e-005,3,9.924961e-001,2.144718e-002,,,,,,,,,,,,,,32,2,4.000000e+000,9.540558e-003,0.000000e+000,0,0,0,
1652418252.531,,7.000000e+003,4.999358e+001,7.054795e-002,1.310767e-005,3,9.924949e-001,1.857980e-002,,,,,,,,,,,,,,32,2,4.000000e+000,9.540558e-003,0.000000e+000,0,0,0,
1652418375.921,,7.500000e+003,4.999596e+001,7.511279e-002,1.130063e-005,3,9.924366e-001,1.504488e-002,,,,,,,,,,,,,,32,2,4.000000e+000,7.160187e-003,0.000000e+000,0,0,0,
1652418504.531,,8.000000e+003,4.999805e+001,7.964890e-002,1.552585e-005,3,9.924440e-001,1.949286e-002,,,,,,,,,,,,,,32,2,4.000000e+000,9.540558e-003,0.000000e+000,0,0,0,
1652418630.234,,8.500000e+003,4.999894e+001,8.415991e-002,1.814422e-005,3,9.924395e-001,2.155922e-002,,,,,,,,,,,,,,32,2,4.000000e+000,4.760742e-003,0.000000e+000,0,1,0,
1652418769.109,,9.000000e+003,4.999864e+001,8.863255e-002,3.830099e-006,3,9.927099e-001,4.321323e-003,,,,,,,,,,,,,,32,2,4.000000e+000,2.028275e-002,0.000000e+000,0,1,0,
1652418896.875,,9.500000e+003,5.000043e+001,9.313214e-002,3.130984e-005,3,9.923860e-001,3.361873e-002,,,,,,,,,,,,,,32,2,4.000000e+000,4.772186e-003,0.000000e+000,0,1,0,
1652419022.531,,1.000000e+004,4.999894e+001,9.757329e-002,2.245373e-005,3,9.924765e-001,2.301217e-002,,,,,,,,,,,,,,32,2,4.000000e+000,2.380371e-003,0.000000e+000,0,1,0,
1652419159.687,,1.200000e+004,4.999596e+001,1.152792e-001,2.334935e-005,3,9.924315e-001,2.025460e-002,,,,,,,,,,,,,,32,2,4.000000e+000,4.768372e-003,0.000000e+000,0,1,0,
1652419287.187,,1.400000e+004,4.999626e+001,1.328462e-001,3.771090e-005,3,9.924188e-001,2.838688e-002,,,,,,,,,,,,,,32,2,4.000000e+000,7.160187e-003,0.000000e+000,0,0,0,
1652419417.796,,1.600000e+004,5.000401e+001,1.503100e-001,5.234639e-005,3,9.923313e-001,3.482562e-002,,,,,,,,,,,,,,32,2,4.000000e+000,1.549911e-002,0.000000e+000,0,0,0,
1652419546.781,,1.800000e+004,4.999745e+001,1.676693e-001,5.386367e-005,3,9.923230e-001,3.212496e-002,,,,,,,,,,,,,,32,2,4.000000e+000,7.148743e-003,0.000000e+000,0,0,0,
1652419700.359,,2.000000e+004,4.999834e+001,1.848947e-001,1.958775e-005,3,9.926370e-001,1.059401e-002,,,,,,,,,,,,,,32,2,4.000000e+000,3.570557e-003,0.000000e+000,0,0,0,
1652419833.421,,2.200000e+004,4.999417e+001,2.021393e-001,5.661376e-005,3,9.923159e-001,2.800730e-002,,,,,,,,,,,,,,32,2,4.000000e+000,1.908112e-002,0.000000e+000,0,1,0,
1652419963.125,,2.400000e+004,4.999805e+001,2.192701e-001,6.208230e-005,3,9.922682e-001,2.831317e-002,,,,,,,,,,,,,,32,2,4.000000e+000,8.350372e-003,0.000000e+000,0,1,0,
1652420103.140,,2.600000e+004,5.000043e+001,2.363476e-001,5.605531e-005,3,9.923081e-001,2.371732e-002,,,,,,,,,,,,,,32,2,4.000000e+000,1.549911e-002,0.000000e+000,0,1,0,
1652420237.812,,2.800000e+004,5.000103e+001,2.533727e-001,7.453671e-005,3,9.922751e-001,2.941781e-002,,,,,,,,,,,,,,32,2,4.000000e+000,4.772186e-003,0.000000e+000,0,1,0,
1652420371.140,,3.000000e+004,4.999566e+001,2.703497e-001,7.843528e-005,3,9.922520e-001,2.901253e-002,,,,,,,,,,,,,,32,2,4.000000e+000,5.970001e-003,0.000000e+000,0,1,0,
1652420507.515,,3.200000e+004,4.999506e+001,2.872606e-001,9.295488e-005,3,9.922971e-001,3.235908e-002,,,,,,,,,,,,,,32,2,4.000000e+000,5.970001e-003,0.000000e+000,0,1,0,
1652420645.250,,3.400000e+004,4.999506e+001,3.041289e-001,8.515771e-005,3,9.923078e-001,2.800053e-002,,,,,,,,,,,,,,32,2,4.000000e+000,1.906967e-002,0.000000e+000,0,1,0,
1652420781.453,,3.600000e+004,4.999775e+001,3.209662e-001,7.143891e-005,3,9.922931e-001,2.225746e-002,,,,,,,,,,,,,,32,2,4.000000e+000,4.760742e-003,0.000000e+000,0,1,0,
1652420918.015,,3.800000e+004,4.999775e+001,3.378008e-001,1.108041e-004,3,9.922982e-001,3.280160e-002,,,,,,,,,,,,,,32,2,4.000000e+000,4.760742e-003,0.000000e+000,0,0,0,
1652421060.687,,4.000000e+004,4.999924e+001,3.545375e-001,8.557918e-005,3,9.923256e-001,2.413826e-002,,,,,,,,,,,,,,32,2,4.000000e+000,1.191711e-002,0.000000e+000,0,0,0,
1652421196.062,,4.200000e+004,4.999983e+001,3.712807e-001,1.114152e-004,3,9.922507e-001,3.000835e-002,,,,,,,,,,,,,,32,2,4.000000e+000,4.760742e-003,0.000000e+000,0,1,0,
1652421331.390,,4.400000e+004,4.999983e+001,3.879715e-001,8.083766e-005,3,9.922720e-001,2.083598e-002,,,,,,,,,,,,,,32,2,4.000000e+000,4.760742e-003,0.000000e+000,0,1,0,
1652421465.796,,4.600000e+004,4.999447e+001,4.046748e-001,1.197181e-004,3,9.922684e-001,2.958378e-002,,,,,,,,,,,,,,32,2,4.000000e+000,7.160187e-003,0.000000e+000,0,1,0,
1652421604.156,,4.800000e+004,4.999655e+001,4.213443e-001,1.042502e-004,3,9.922968e-001,2.474229e-002,,,,,,,,,,,,,,32,2,4.000000e+000,1.431274e-002,0.000000e+000,0,1,0,
1652421749.156,,5.000000e+004,4.999507e+001,4.380172e-001,7.325122e-005,3,9.923038e-001,1.672337e-002,,,,,,,,,,,,,,32,2,4.000000e+000,4.768372e-003,0.000000e+000,0,1,0,